Workbook

Sheet Summary
A1: InvenTree Parts — UI / Manual Test Suite Summary
A2: Optimised suite with end-to-end flows. Requirements source: docs.inventree.org/en/stable/part/ and sub-pages (Creating a Part, Part Views, Templates, Revisions, Virtual, Trackable, Test Templates) plus Units, Parameters and Data Import. Target build: InvenTree 1.5.x.
A4: Module | B4: Test cases | C4: Positive | D4: Negative | E4: Boundary
A5: Part Creation | B5: =COUNTIF('Test Cases'!$B:$B,$A5) | C5: =COUNTIFS('Test Cases'!$B:$B,$A5,'Test Cases'!$D:$D,"Positive") | D5: =COUNTIFS('Test Cases'!$B:$B,$A5,'Test Cases'!$D:$D,"Negative") | E5: =COUNTIFS('Test Cases'!$B:$B,$A5,'Test Cases'!$D:$D,"Boundary")
A6: Part Import | B6: =COUNTIF('Test Cases'!$B:$B,$A6) | C6: =COUNTIFS('Test Cases'!$B:$B,$A6,'Test Cases'!$D:$D,"Positive") | D6: =COUNTIFS('Test Cases'!$B:$B,$A6,'Test Cases'!$D:$D,"Negative") | E6: =COUNTIFS('Test Cases'!$B:$B,$A6,'Test Cases'!$D:$D,"Boundary")
A7: Part Detail | B7: =COUNTIF('Test Cases'!$B:$B,$A7) | C7: =COUNTIFS('Test Cases'!$B:$B,$A7,'Test Cases'!$D:$D,"Positive") | D7: =COUNTIFS('Test Cases'!$B:$B,$A7,'Test Cases'!$D:$D,"Negative") | E7: =COUNTIFS('Test Cases'!$B:$B,$A7,'Test Cases'!$D:$D,"Boundary")
A8: Detail Tabs | B8: =COUNTIF('Test Cases'!$B:$B,$A8) | C8: =COUNTIFS('Test Cases'!$B:$B,$A8,'Test Cases'!$D:$D,"Positive") | D8: =COUNTIFS('Test Cases'!$B:$B,$A8,'Test Cases'!$D:$D,"Negative") | E8: =COUNTIFS('Test Cases'!$B:$B,$A8,'Test Cases'!$D:$D,"Boundary")
A9: Categories | B9: =COUNTIF('Test Cases'!$B:$B,$A9) | C9: =COUNTIFS('Test Cases'!$B:$B,$A9,'Test Cases'!$D:$D,"Positive") | D9: =COUNTIFS('Test Cases'!$B:$B,$A9,'Test Cases'!$D:$D,"Negative") | E9: =COUNTIFS('Test Cases'!$B:$B,$A9,'Test Cases'!$D:$D,"Boundary")
A10: Parameters | B10: =COUNTIF('Test Cases'!$B:$B,$A10) | C10: =COUNTIFS('Test Cases'!$B:$B,$A10,'Test Cases'!$D:$D,"Positive") | D10: =COUNTIFS('Test Cases'!$B:$B,$A10,'Test Cases'!$D:$D,"Negative") | E10: =COUNTIFS('Test Cases'!$B:$B,$A10,'Test Cases'!$D:$D,"Boundary")
A11: Part Attributes | B11: =COUNTIF('Test Cases'!$B:$B,$A11) | C11: =COUNTIFS('Test Cases'!$B:$B,$A11,'Test Cases'!$D:$D,"Positive") | D11: =COUNTIFS('Test Cases'!$B:$B,$A11,'Test Cases'!$D:$D,"Negative") | E11: =COUNTIFS('Test Cases'!$B:$B,$A11,'Test Cases'!$D:$D,"Boundary")
A12: Units of Measure | B12: =COUNTIF('Test Cases'!$B:$B,$A12) | C12: =COUNTIFS('Test Cases'!$B:$B,$A12,'Test Cases'!$D:$D,"Positive") | D12: =COUNTIFS('Test Cases'!$B:$B,$A12,'Test Cases'!$D:$D,"Negative") | E12: =COUNTIFS('Test Cases'!$B:$B,$A12,'Test Cases'!$D:$D,"Boundary")
A13: Revisions | B13: =COUNTIF('Test Cases'!$B:$B,$A13) | C13: =COUNTIFS('Test Cases'!$B:$B,$A13,'Test Cases'!$D:$D,"Positive") | D13: =COUNTIFS('Test Cases'!$B:$B,$A13,'Test Cases'!$D:$D,"Negative") | E13: =COUNTIFS('Test Cases'!$B:$B,$A13,'Test Cases'!$D:$D,"Boundary")
A14: Negative & Boundary | B14: =COUNTIF('Test Cases'!$B:$B,$A14) | C14: =COUNTIFS('Test Cases'!$B:$B,$A14,'Test Cases'!$D:$D,"Positive") | D14: =COUNTIFS('Test Cases'!$B:$B,$A14,'Test Cases'!$D:$D,"Negative") | E14: =COUNTIFS('Test Cases'!$B:$B,$A14,'Test Cases'!$D:$D,"Boundary")
A15: End-to-End Flows | B15: =COUNTIF('Test Cases'!$B:$B,$A15) | C15: =COUNTIFS('Test Cases'!$B:$B,$A15,'Test Cases'!$D:$D,"Positive") | D15: =COUNTIFS('Test Cases'!$B:$B,$A15,'Test Cases'!$D:$D,"Negative") | E15: =COUNTIFS('Test Cases'!$B:$B,$A15,'Test Cases'!$D:$D,"Boundary")
A16: Total | B16: =SUM(B5:B15) | C16: =SUM(C5:C15) | D16: =SUM(D5:D15) | E16: =SUM(E5:E15)
A18: Execution status | B18: Test cases
A19: Not Run | B19: =COUNTIF('Test Cases'!$L:$L,$A19)
A20: Pass | B20: =COUNTIF('Test Cases'!$L:$L,$A20)
A21: Fail | B21: =COUNTIF('Test Cases'!$L:$L,$A21)
A22: Blocked | B22: =COUNTIF('Test Cases'!$L:$L,$A22)
A25: Priority | B25: Test cases
A26: P1 | B26: =COUNTIF('Test Cases'!$E:$E,$A26)
A27: P2 | B27: =COUNTIF('Test Cases'!$E:$E,$A27)
A28: P3 | B28: =COUNTIF('Test Cases'!$E:$E,$A28)
A30: Release execution plan
A31: Release | B31: Cadence | C31: Scope | D31: Test cases | E31: Entry criteria | F31: Exit criteria
A32: Minor release | B32: Bi-weekly | C32: All P1 cases (includes core E2E flows); add P2 cases only for modules changed in the release | D32: =COUNTIF('Test Cases'!$E:$E,"P1") | E32: Build deployed to QA; release notes available; P1 cases pass on smoke | F32: All P1 pass; no open Critical/High defects; fixed defects retested
A33: Major release | B33: Quarterly | C33: Full pack, including all E2E flows, run with default and non-default global settings (see Observations) | D33: =COUNTA('Test Cases'!$A:$A)-1 | E33: Feature-complete build on QA; DB migrations applied; P1 cases pass on smoke | F33: All cases executed; pass rate >= 98%; no open Critical/High defects

Sheet Test Cases
A1: TC ID | B1: Module | C1: Title / Scenario | D1: Type | E1: Priority | F1: Preconditions | G1: Navigation | H1: Test Data | I1: Steps | J1: Expected Result | K1: Actual Result | L1: Status | M1: Remarks | N1: Requirement Source
A2: UI-CRT-001 | B2: Part Creation | C2: Create part with required field only | D2: Positive | E2: P1 | F2: Logged in as user with Part view/add/change/delete roles | G2: Parts > Parts table > Add Parts > Create Part | H2: Name='UI-Resistor-01' | I2: 1. Add Parts > Create Part 2. Enter Name 3. Submit | J2: Redirects to new part detail page; part listed in Parts table | L2: Not Run | N2: part/create
A3: UI-CRT-002 | B3: Part Creation | C3: Create part with all optional fields | D3: Positive | E3: P1 | F3: Logged in as user with Part view/add/change/delete roles; category and stock location exist | G3: Parts > Parts table > Create Part | H3: Category, IPN, Description, Revision, Keywords, Units=m, Link, Min/Max stock, Default location, Notes | I3: 1. Fill every field 2. Submit 3. Open Details panel | J3: All values saved and displayed as entered; breadcrumb shows category path | L3: Not Run | N3: part/create
A4: UI-CRT-003 | B4: Part Creation | C4: Form validation: required Name and invalid Link | D4: Negative | E4: P1 | F4: Logged in as user with Part view/add/change/delete roles | G4: Parts > Parts table > Create Part | H4: Name blank; Link='not a url' | I4: 1. Submit with Name blank 2. Enter Name, set invalid Link, submit 3. Correct Link, submit | J4: Steps 1-2: inline field errors, entered data kept, no part created. Step 3: part created | L4: Not Run | N4: part/create
A5: UI-CRT-004 | B5: Part Creation | C5: Initial stock on create (setting-dependent) | D5: Positive | E5: P1 | F5: Logged in as user with Part view/add/change/delete roles; stock location exists | G5: Parts > Parts table > Create Part | H5: Qty=25, Location=Store A | I5: 1. With 'Create Initial Stock' setting OFF, open form 2. Turn setting ON, reopen form 3. Tick Create Initial Stock, enter qty and location, submit | J5: OFF: no initial stock section. ON: section shown; one stock item of 25 created at Store A | L5: Not Run | N5: part/create
A6: UI-CRT-005 | B6: Part Creation | C6: Supplier and manufacturer data on create (Purchaseable only) | D6: Positive | E6: P1 | F6: Logged in as user with Part view/add/change/delete roles; supplier and manufacturer companies exist | G6: Parts > Parts table > Create Part | H6: Supplier=ACME, SKU=AC-100, Manufacturer=MfgCo, MPN=M-100 | I6: 1. Toggle Purchaseable off/on and observe form 2. With Purchaseable on, tick Add Supplier Data, fill, submit 3. Open Suppliers tab | J6: 'Add Supplier Data' only offered when Purchaseable; supplier part AC-100 and manufacturer part M-100 linked to the new part | L6: Not Run | N6: part/create
A7: UI-CRT-006 | B7: Part Creation | C7: Create part from a category pre-fills category | D7: Positive | E7: P2 | F7: Logged in as user with Part view/add/change/delete roles | G7: Category page > Add Parts > Create Part | H7: Category 'Resistors' | I7: 1. Open category 2. Create part | J7: Category field pre-filled; part listed in that category | L7: Not Run | N7: part/create
A8: UI-CRT-007 | B8: Part Creation | C8: Part image: upload, select existing, delete | D8: Positive | E8: P2 | F8: Logged in as user with Part view/add/change/delete roles; PNG/JPG file | G8: Part detail page > image hover menu | H8: image.png | I8: 1. Upload new image 2. Select from existing images 3. Delete image | J8: Image and table thumbnail update each time; placeholder shown after delete | L8: Not Run | N8: part/index
A9: UI-CRT-008 | B9: Part Creation | C9: Create/import options hidden without Part create permission | D9: Negative | E9: P1 | F9: User with Part view role only | G9: Parts > Parts table | H9: - | I9: 1. Log in as view-only user 2. Open Parts | J9: 'Add Parts' menu not displayed | L9: Not Run | N9: part/create
A10: UI-IMP-001 | B10: Part Import | C10: Import parts from CSV with column mapping | D10: Positive | E10: P1 | F10: Staff user with Part change permission | G10: Parts > Parts table > Add Parts > Import from File | H10: parts.csv: 5 rows; headers 'Name', 'Desc', 'Category' | I10: 1. Upload file 2. Review auto-mapping; map 'Desc' manually 3. Load data 4. Select all rows > Import | J10: Matching headers auto-mapped; manual mapping accepted; all rows 'Imported'; parts visible in table | L10: Not Run | N10: concepts/data_import
A11: UI-IMP-002 | B11: Part Import | C11: Invalid rows flagged, corrected or removed | D11: Negative | E11: P1 | F11: As UI-IMP-001 | G11: Parts > Parts table > Import from File | H11: Rows with blank Name, unknown category ID | I11: 1. Upload and map 2. Review row status 3. Fix one invalid row and re-process 4. Delete the other 5. Import | J11: Invalid rows show 'Error' with message; corrected row imports; deleted row not imported | L11: Not Run | N11: concepts/data_import
A12: UI-IMP-003 | B12: Part Import | C12: Update existing parts via export > edit > import | D12: Positive | E12: P2 | F12: Staff user; parts exist | G12: Admin Center > Import data | H12: Exported CSV with ID column, descriptions edited | I12: 1. Export parts 2. Edit descriptions 3. New session with 'Update Existing Records'; map ID 4. Import | J12: Existing parts updated; no duplicates created | L12: Not Run | N12: concepts/data_import
A13: UI-IMP-004 | B13: Part Import | C13: Import unavailable to non-staff user | D13: Negative | E13: P2 | F13: Non-staff user with Part view role | G13: Parts > Parts table | H13: - | I13: 1. Open Add Parts menu | J13: 'Import from File' not offered (or import rejected) | L13: Not Run | N13: concepts/data_import
... A18: UI-DET-005 | B18: Part Detail | C18: Low stock and overstock indicators | D18: Positive | E18: P2 | F18: Part with Min=10, Max=100 | G18: Part detail page; Parts table | H18: Stock 5, then 150 | I18: 1. Set stock to 5 2. Set stock to 150 | J18: Flagged 'low stock' at 5 and 'overstocked' at 150 | L18: Not Run | N18: part/index
A19: UI-TAB-001 | B19: Detail Tabs | C19: Tab visibility follows part attributes (matrix) | D19: Positive | E19: P1 | F19: Parts: (a) plain, (b) Assembly, (c) Component, (d) Template, (e) Purchaseable, (f) Salable, (g) Testable, (h) Virtual | G19: Part detail page | H19: One part per flag set | I19: 1. Open each part 2. Record which tabs are shown 3. Toggle a flag on part (a) and refresh | J19: BOM + Build Orders only for Assembly; Used In for Component; Variants for Template; Suppliers + Purchase Orders for Purchaseable; Sales Orders for Salable; Allocations for Component or Salable (not Virtual); Test Templates + Test Results for Testable; Stock hidden for Virtual. Toggling a flag shows/hides its tabs | L19: Not Run | M19: See OBS-04 | N19: part/views
A20: UI-TAB-002 | B20: Detail Tabs | C20: Stock tab: list, add stock, bulk actions, export | D20: Positive | E20: P1 | F20: Part with 3 stock items in 2 locations | G20: Part detail page > Stock | H20: New item qty 10 | I20: 1. Review table 2. New Stock Item qty 10 3. Select 2 rows > stock actions 4. Export | J20: Items show qty, location, status; new item added and total +10; actions enabled only with selection; export file downloads | L20: Not Run | N20: part/views
A21: UI-TAB-003 | B21: Detail Tabs | C21: BOM tab: add, edit and delete BOM item | D21: Positive | E21: P1 | F21: Assembly part; component part | G21: Part detail page > Bill of Materials | H21: Component X qty 4 → 6 | I21: 1. Add item 2. Edit qty 3. Delete item | J21: Each change reflected in BOM table | L21: Not Run | N21: part/views
A22: UI-TAB-004 | B22: Detail Tabs | C22: Allocations tab shows build and sales order allocations | D22: Positive | E22: P2 | F22: Component allocated to a build and a sales order | G22: Part detail page > Allocations | H22: - | I22: 1. Open tab | J22: Both allocations listed with quantities | L22: Not Run | N22: part/views
A23: UI-TAB-005 | B23: Detail Tabs | C23: Build Orders tab lists builds | D23: Positive | E23: P2 | F23: Assembly with 2 build orders | G23: Part detail page > Build Orders | H23: - | I23: 1. Open tab | J23: Both builds listed with quantity, status and dates | L23: Not Run | N23: part/views
A24: UI-TAB-006 | B24: Detail Tabs | C24: Parameters tab: add, edit, delete | D24: Positive | E24: P1 | F24: Template 'Resistance' (ohm) | G24: Part detail page > Parameters | H24: 10k → 22k | I24: 1. Add parameter 2. Edit value 3. Delete | J24: Value stored with unit; edit saved; row removed after delete | L24: Not Run | N24: concepts/parameters
A25: UI-TAB-007 | B25: Detail Tabs | C25: Attachments: file and link | D25: Positive | E25: P2 | F25: Logged in as user with Part view/add/change/delete roles | G25: Part detail page > Attachments | H25: datasheet.pdf; https://example.com/ds | I25: 1. Upload file with comment 2. Add link 3. Download file 4. Delete both | J25: Both listed; file downloads intact; link opens URL; removed after delete | L25: Not Run | N25: part/views
A26: UI-TAB-008 | B26: Detail Tabs | C26: Related Parts: add, view from both sides, remove; hidden when disabled | D26: Positive | E26: P2 | F26: Two parts; Related Parts setting on | G26: Part detail page > Related Parts | H26: Part B | I26: 1. Relate Part B 2. Open Part B 3. Remove relation 4. Disable setting | J26: Relation shown on both parts and removed from both; tab hidden when setting off | L26: Not Run | N26: part/views
A27: UI-TAB-009 | B27: Detail Tabs | C27: Test Templates: create; key generated; duplicate name rejected | D27: Positive | E27: P1 | F27: Testable part | G27: Part detail page > Test Templates | H27: 'Firmware Version' (twice) | I27: 1. Add template (Required, Requires Value) 2. Add same name again | J27: First created with key 'firmwareversion'; duplicate rejected with error | L27: Not Run | N27: part/test
A28: UI-TAB-010 | B28: Detail Tabs | C28: Test templates cascade to variants | D28: Positive | E28: P2 | F28: Testable template part with variant | G28: Part detail page (variant) > Test Templates | H28: - | I28: 1. Add template on master 2. Open variant | J28: Master's template listed on the variant | L28: Not Run | N28: part/test
A29: UI-CAT-001 | B29: Categories | C29: Create nested categories; sub-categories and counts | D29: Positive | E29: P1 | F29: Logged in as user with Part view/add/change/delete roles | G29: Parts > Categories > New Category | H29: Electronics > Passives > Resistors | I29: 1. Create 3 levels 2. Open each level | J29: Tree and breadcrumbs correct; sub-categories listed with part counts | L29: Not Run | N29: part/index
A30: UI-CAT-002 | B30: Categories | C30: Category part list includes sub-category parts | D30: Positive | E30: P1 | F30: Parts in Passives and Resistors | G30: Category 'Passives' | H30: - | I30: 1. Open Passives | J30: Parts from both Passives and Resistors listed; name links to part detail | L30: Not Run | N30: part/index
A31: UI-CAT-003 | B31: Categories | C31: Filter and search category parts | D31: Positive | E31: P1 | F31: Mixed parts in category | G31: Category page > Filters / search | H31: Active=Yes + Assembly=Yes; partial name | I31: 1. Apply filters singly, then combined 2. Search partial name 3. Clear all | J31: Results match each filter (AND when combined) and the search; clear restores list | L31: Not Run | N31: part/index
... A56: UI-REV-001 | B56: Revisions | C56: Create revision via Duplicate Part | D56: Positive | E56: P1 | F56: Assembly 'Board' rev A | G56: Part detail page > actions > Duplicate Part | H56: Revision Of=Board, Revision=B | I56: 1. Duplicate 2. Set Revision Of and Revision 3. Submit | J56: Redirect to new part linked to Board as revision B | L56: Not Run | N56: part/revision
A57: UI-REV-002 | B57: Revisions | C57: Revision selector shown only when revisions exist | D57: Positive | E57: P2 | F57: Parts with and without revisions | G57: Part detail page | H57: - | I57: 1. Open part without revisions 2. Open part with revisions and switch | J57: Selector hidden / shown and navigates correctly | L57: Not Run | M57: See OBS-03 | N57: part/revision
A58: UI-REV-003 | B58: Revisions | C58: Part cannot be a revision of itself | D58: Negative | E58: P1 | F58: Part 'Board' | G58: Part detail page > Edit | H58: Revision Of = Board | I58: 1. Submit | J58: Error 'Part cannot be a revision of itself' | L58: Not Run | N58: part/revision
A59: UI-REV-004 | B59: Revisions | C59: Revision code unique per part and mandatory | D59: Negative | E59: P1 | F59: Board has revision B | G59: Part detail page > Duplicate Part | H59: Revision=B; Revision blank | I59: 1. Submit with B 2. Submit with blank revision | J59: 'Duplicate part revision already exists.'; revision code required error | L59: Not Run | N59: part/revision
A60: UI-REV-005 | B60: Revisions | C60: Template part cannot have revisions | D60: Negative | E60: P1 | F60: Template 'Widget' | G60: Part detail page > Duplicate Part | H60: Revision Of=Widget | I60: 1. Submit | J60: Error 'Cannot make a revision of a template part' | L60: Not Run | N60: part/revision
A61: UI-REV-006 | B61: Revisions | C61: Variant revisions must reference the same template | D61: Negative | E61: P2 | F61: Variant Widget-01 of Widget; template Gadget | G61: Part detail page > Duplicate Part | H61: Revision Of=Widget-01 with Variant Of=Widget, then Variant Of=Gadget | I61: 1. Submit with Widget 2. Submit with Gadget | J61: Widget: revision created. Gadget: 'Parent part must point to the same template' | L61: Not Run | N61: part/revision
A62: UI-REV-007 | B62: Revisions | C62: Revision of a revision is prevented | D62: Negative | E62: P1 | F62: Board rev B | G62: Part detail page > Duplicate Part | H62: Revision Of = Board rev B, Revision=C | I62: 1. Submit | J62: Error; revisions must reference the original part | L62: Not Run | M62: See OBS-01 | N62: part/revision
A63: UI-REV-008 | B63: Revisions | C63: Revision settings enforced | D63: Negative | E63: P2 | F63: Toggle PART_REVISION_ASSEMBLY_ONLY and PART_ENABLE_REVISION | G63: Part detail page > Duplicate Part | H63: Non-assembly part | I63: 1. ASSEMBLY_ONLY on: make revision of non-assembly 2. ENABLE_REVISION off: open form | J63: 1: 'Revisions are only allowed for assembly parts'. 2: revision fields and selector not available | L63: Not Run | N63: part/revision
A64: UI-NEG-001 | B64: Negative & Boundary | C64: Duplicate IPN per setting | D64: Negative | E64: P1 | F64: IPN 'R-001' exists | G64: Parts > Parts table > Create Part | H64: IPN='R-001' | I64: 1. Default settings: submit 2. Disable Allow Duplicate IPN: submit again | J64: Default: created. Disabled: 'Duplicate IPN not allowed in part settings' | L64: Not Run | M64: See OBS-02 | N64: part/index
A65: UI-NEG-002 | B65: Negative & Boundary | C65: Same Name + IPN + Revision rejected | D65: Negative | E65: P1 | F65: Part X / IPN Y / Rev A | G65: Parts > Parts table > Create Part | H65: Same values | I65: 1. Submit | J65: 'Part with this Name, IPN and Revision already exists.' | L65: Not Run | N65: part/views
A66: UI-NEG-003 | B66: Negative & Boundary | C66: Field boundaries: lengths and negative numbers | D66: Boundary | E66: P2 | F66: Logged in as user with Part view/add/change/delete roles | G66: Parts > Parts table > Create Part | H66: Name/IPN 100 & 101 chars; Description 250 & 251; Min stock -1; Default expiry -1 | I66: 1. Submit max values 2. Submit max+1 and negative values | J66: Max accepted; max+1 and negatives show field errors | L66: Not Run | N66: part/views
A67: UI-NEG-004 | B67: Negative & Boundary | C67: HTML / script in text fields rejected | D67: Negative | E67: P2 | F67: Logged in as user with Part view/add/change/delete roles | G67: Parts > Parts table > Create Part | H67: Name='<script>alert(1)</script>' | I67: 1. Submit | J67: 'Remove HTML tags from this value'; nothing executed | L67: Not Run | N67: part/views
A68: UI-E2E-001 | B68: End-to-End Flows | C68: Procure to stock: new purchaseable part through purchase order receipt | D68: Positive | E68: P1 | F68: Supplier ACME; stock location 'Store A' | G68: Parts > Create Part → Purchasing > Purchase Orders | H68: Part 'Cap-100nF', default location Store A, SKU AC-100, qty 500 | I68: 1. Create purchaseable part with default location and supplier data 2. Create PO for ACME, add line AC-100 x500 3. Issue PO 4. Receive all items 5. Open part > Stock and Purchase Orders tabs | J68: PO line offered only this supplier part; receipt creates 500 in stock at Store A; part In Stock = 500; PO shown on Purchase Orders tab as complete | L68: Not Run | N68: part/create
...

Sheet Traceability
A1: Requirement → test case traceability (Phase 1 brief)
A3: Req | B3: Requirement (from brief) | C3: TC ID prefixes | D3: Test cases
A4: R1 | B4: Part creation – manual entry | C4: UI-CRT-* | D4: =COUNTIF('Test Cases'!$A:$A,"UI-CRT-*")
A5: R2 | B5: Part creation – import flows | C5: UI-IMP-* | D5: =COUNTIF('Test Cases'!$A:$A,"UI-IMP-*")
A6: R3 | B6: Part detail view – header, details and all tabs | C6: UI-DET-*, UI-TAB-* | D6: =COUNTIF('Test Cases'!$A:$A,"UI-DET-*")+COUNTIF('Test Cases'!$A:$A,"UI-TAB-*")
A7: R4 | B7: Part categories – hierarchy, filtering, parametric tables | C7: UI-CAT-*, UI-PRM-* | D7: =COUNTIF('Test Cases'!$A:$A,"UI-CAT-*")+COUNTIF('Test Cases'!$A:$A,"UI-PRM-*")
A8: R5 | B8: Part attributes – Virtual, Template, Assembly, Component, Trackable, Purchaseable, Salable, Active/Inactive | C8: UI-ATT-* | D8: =COUNTIF('Test Cases'!$A:$A,"UI-ATT-*")
A9: R6 | B9: Units of measure configuration | C9: UI-UOM-* | D9: =COUNTIF('Test Cases'!$A:$A,"UI-UOM-*")
A10: R7 | B10: Part revisions – creation and constraints | C10: UI-REV-* | D10: =COUNTIF('Test Cases'!$A:$A,"UI-REV-*")
A11: R8 | B11: Negative and boundary scenarios | C11: UI-NEG-* (+ negative cases in every module) | D11: =COUNTIF('Test Cases'!$A:$A,"UI-NEG-*")
A12: R9 | B12: End-to-end business flows across modules | C12: UI-E2E-* | D12: =COUNTIF('Test Cases'!$A:$A,"UI-E2E-*")

Sheet Observations
A1: Requirement analysis observations
A3: ID | B3: Type | C3: Observation | D3: Impact on testing
A4: OBS-01 | B4: Requirement gap | C4: 'Revision-of-revision' prevention is required by the brief but is not listed in the Part Revisions doc, and no such check exists in the part model validation (InvenTree stable source). | D4: UI-REV-007 is likely to fail; confirm the intended behaviour with the product owner before logging a defect.
A5: OBS-02 | B5: Setting-dependent | C5: Duplicate IPNs are allowed by default (PART_ALLOW_DUPLICATE_IPN = True). The negative scenario only applies with the setting disabled. | D5: UI-NEG-001 covers both states.
A6: OBS-03 | B6: UI structure | C6: There is no dedicated 'Revisions' tab. Revisions are navigated with the 'Select Part Revision' drop-down, which appears only when revisions exist. | D6: Covered by UI-REV-002.
A7: OBS-04 | B7: Tab visibility | C7: The tabs shown depend on part flags and user roles. | D7: Consolidated into the UI-TAB-001 matrix.
A8: OBS-05 | B8: Configuration | C8: Several cases depend on global settings (Create Initial Stock, Part Locking, Revisions, Related Parts, Allow Duplicate IPN). Record the setting state in Actual Result. | D8: Reset settings to defaults after each run.

Sheet Automation Traceability 
A1: TC ID | B1: Automated | C1: Test Class.Method | D1: Coverage Note
A2: UI-CRT-001 | B2: Partial | C2: InvenTreePartUITest.createPartWithOnlyRequiredName | D2: Part is created with Name only and confirmed via the API and the Category's Parts table; this TC's specific 'redirects to part detail page' expected result is not asserted.
A3: UI-CRT-002 | B3: Partial | C3: InvenTreePartUITest.createPartWithAllOptionalFields | D3: Covers IPN, Description, Units and Link - each set on creation, verified via the API and read back from the Part Details tab. Revision, Keywords, Min/Max stock, Default location, Notes and the breadcrumb category-path assertion this TC specifies are not covered.
A4: UI-CRT-003 | B4: Yes | C4: InvenTreePartUITest.partCreationFullValidationFlow | D4: Full match: blank-Name inline error, invalid-Link inline error, then a corrected resubmit on the same modal instance succeeds and the Part is verified via the API.
A5: UI-CRT-004 | B5: No
A6: UI-CRT-005 | B6: No
A7: UI-CRT-006 | B7: Partial | C7: InvenTreePartUITest.createPartWithOnlyRequiredName (and every other Part-creation test) | D7: Every automated Part-creation test creates the Part from within a Category's own Parts tab and confirms afterward that it is listed there, but none explicitly assert that the Category field itself arrives pre-filled in the modal.
A8: UI-CRT-007 | B8: No
A9: UI-CRT-008 | B9: No
A10: UI-IMP-001 | B10: No
A11: UI-IMP-002 | B11: No
A12: UI-IMP-003 | B12: No
A13: UI-IMP-004 | B13: No
A14: UI-DET-001 | B14: No
A15: UI-DET-002 | B15: Partial | C15: InvenTreePartUITest.createPartWithAllOptionalFields | D15: Confirms IPN, Description and Units are shown on the Part Details tab; Revision, Keywords, Link, creation date and creation user are not asserted there.
A16: UI-DET-003 | B16: Partial | C16: InvenTreePartUITest.editPartNameUpdatesDetailPage | D16: Same Edit-modal mechanism, but edits Name, not Description; notes/markdown editing is not covered.
A17: UI-DET-004 | B17: No
A18: UI-DET-005 | B18: No
A19: UI-TAB-001 | B19: No
A20: UI-TAB-002 | B20: Partial | C20: InvenTreeCrossFunctionalFlowUITest.createPartAddParameterAddStockAndVerifyInCategoryView | D20: Covers only "add a stock item" and the resulting status badge/category-table update; table review of pre-existing items, bulk actions and export are not covered.
A21: UI-TAB-003 | B21: No
A22: UI-TAB-004 | B22: No
A23: UI-TAB-005 | B23: No
A24: UI-TAB-006 | B24: Partial | C24: InvenTreeCrossFunctionalFlowUITest.createPartAddParameterAddStockAndVerifyInCategoryView (add) + InvenTreePartParametersUITest.editParameterValueUpdatesTable / .deleteParameterRemovesItFromTable (edit, delete) | D24: Add, edit and delete are each independently verified, but by separate tests against separately-created Parameters - not as one continuous add-this-row / edit-it / delete-it flow on the same row.
A25: UI-TAB-007 | B25: No
A26: UI-TAB-008 | B26: No
A27: UI-TAB-009 | B27: No
A28: UI-TAB-010 | B28: No
A29: UI-CAT-001 | B29: No
A30: UI-CAT-002 | B30: No
A31: UI-CAT-003 | B31: No
A32: UI-CAT-004 | B32: No
A33: UI-CAT-005 | B33: Yes | C33: InvenTreePartCategoryUITest.structuralCategoryRejectsParts | D33: Full match, including the exact error text 'Parts cannot be assigned to structural part categories!'.
A34: UI-CAT-006 | B34: No
A35: UI-CAT-007 | B35: No
A36: UI-CAT-008 | B36: No
A37: UI-PRM-001 | B37: No
A38: UI-PRM-002 | B38: No
A39: UI-PRM-003 | B39: No
A40: UI-PRM-004 | B40: No
...
