Workbook

Sheet Summary
A1: InvenTree Parts & Part Categories API — Test Suite Summary
A2: Source: InvenTree API schema v530 (docs.inventree.org/en/stable/api/schema/part/). Target build: InvenTree 1.5.5.
A4: Module | B4: Test cases | C4: Positive | D4: Negative | E4: Boundary
A5: Part CRUD | B5: =COUNTIF('Test Cases'!$B:$B,$A5) | C5: =COUNTIFS('Test Cases'!$B:$B,$A5,'Test Cases'!$D:$D,"Positive") | D5: =COUNTIFS('Test Cases'!$B:$B,$A5,'Test Cases'!$D:$D,"Negative") | E5: =COUNTIFS('Test Cases'!$B:$B,$A5,'Test Cases'!$D:$D,"Boundary")
A6: Category CRUD | B6: =COUNTIF('Test Cases'!$B:$B,$A6) | C6: =COUNTIFS('Test Cases'!$B:$B,$A6,'Test Cases'!$D:$D,"Positive") | D6: =COUNTIFS('Test Cases'!$B:$B,$A6,'Test Cases'!$D:$D,"Negative") | E6: =COUNTIFS('Test Cases'!$B:$B,$A6,'Test Cases'!$D:$D,"Boundary")
A7: Filtering | B7: =COUNTIF('Test Cases'!$B:$B,$A7) | C7: =COUNTIFS('Test Cases'!$B:$B,$A7,'Test Cases'!$D:$D,"Positive") | D7: =COUNTIFS('Test Cases'!$B:$B,$A7,'Test Cases'!$D:$D,"Negative") | E7: =COUNTIFS('Test Cases'!$B:$B,$A7,'Test Cases'!$D:$D,"Boundary")
A8: Pagination | B8: =COUNTIF('Test Cases'!$B:$B,$A8) | C8: =COUNTIFS('Test Cases'!$B:$B,$A8,'Test Cases'!$D:$D,"Positive") | D8: =COUNTIFS('Test Cases'!$B:$B,$A8,'Test Cases'!$D:$D,"Negative") | E8: =COUNTIFS('Test Cases'!$B:$B,$A8,'Test Cases'!$D:$D,"Boundary")
A9: Ordering | B9: =COUNTIF('Test Cases'!$B:$B,$A9) | C9: =COUNTIFS('Test Cases'!$B:$B,$A9,'Test Cases'!$D:$D,"Positive") | D9: =COUNTIFS('Test Cases'!$B:$B,$A9,'Test Cases'!$D:$D,"Negative") | E9: =COUNTIFS('Test Cases'!$B:$B,$A9,'Test Cases'!$D:$D,"Boundary")
A10: Search | B10: =COUNTIF('Test Cases'!$B:$B,$A10) | C10: =COUNTIFS('Test Cases'!$B:$B,$A10,'Test Cases'!$D:$D,"Positive") | D10: =COUNTIFS('Test Cases'!$B:$B,$A10,'Test Cases'!$D:$D,"Negative") | E10: =COUNTIFS('Test Cases'!$B:$B,$A10,'Test Cases'!$D:$D,"Boundary")
A11: Field Validation | B11: =COUNTIF('Test Cases'!$B:$B,$A11) | C11: =COUNTIFS('Test Cases'!$B:$B,$A11,'Test Cases'!$D:$D,"Positive") | D11: =COUNTIFS('Test Cases'!$B:$B,$A11,'Test Cases'!$D:$D,"Negative") | E11: =COUNTIFS('Test Cases'!$B:$B,$A11,'Test Cases'!$D:$D,"Boundary")
A12: Read-only Fields | B12: =COUNTIF('Test Cases'!$B:$B,$A12) | C12: =COUNTIFS('Test Cases'!$B:$B,$A12,'Test Cases'!$D:$D,"Positive") | D12: =COUNTIFS('Test Cases'!$B:$B,$A12,'Test Cases'!$D:$D,"Negative") | E12: =COUNTIFS('Test Cases'!$B:$B,$A12,'Test Cases'!$D:$D,"Boundary")
A13: Relational Integrity | B13: =COUNTIF('Test Cases'!$B:$B,$A13) | C13: =COUNTIFS('Test Cases'!$B:$B,$A13,'Test Cases'!$D:$D,"Positive") | D13: =COUNTIFS('Test Cases'!$B:$B,$A13,'Test Cases'!$D:$D,"Negative") | E13: =COUNTIFS('Test Cases'!$B:$B,$A13,'Test Cases'!$D:$D,"Boundary")
A14: Security | B14: =COUNTIF('Test Cases'!$B:$B,$A14) | C14: =COUNTIFS('Test Cases'!$B:$B,$A14,'Test Cases'!$D:$D,"Positive") | D14: =COUNTIFS('Test Cases'!$B:$B,$A14,'Test Cases'!$D:$D,"Negative") | E14: =COUNTIFS('Test Cases'!$B:$B,$A14,'Test Cases'!$D:$D,"Boundary")
A15: Edge Cases | B15: =COUNTIF('Test Cases'!$B:$B,$A15) | C15: =COUNTIFS('Test Cases'!$B:$B,$A15,'Test Cases'!$D:$D,"Positive") | D15: =COUNTIFS('Test Cases'!$B:$B,$A15,'Test Cases'!$D:$D,"Negative") | E15: =COUNTIFS('Test Cases'!$B:$B,$A15,'Test Cases'!$D:$D,"Boundary")
A16: Schema Contract | B16: =COUNTIF('Test Cases'!$B:$B,$A16) | C16: =COUNTIFS('Test Cases'!$B:$B,$A16,'Test Cases'!$D:$D,"Positive") | D16: =COUNTIFS('Test Cases'!$B:$B,$A16,'Test Cases'!$D:$D,"Negative") | E16: =COUNTIFS('Test Cases'!$B:$B,$A16,'Test Cases'!$D:$D,"Boundary")
A17: Total | B17: =SUM(B5:B16) | C17: =SUM(C5:C16) | D17: =SUM(D5:D16) | E17: =SUM(E5:E16)
A19: Execution status | B19: Test cases
A20: Not Run | B20: =COUNTIF('Test Cases'!$M:$M,$A20)
A21: Pass | B21: =COUNTIF('Test Cases'!$M:$M,$A21)
A22: Fail | B22: =COUNTIF('Test Cases'!$M:$M,$A22)
A23: Blocked | B23: =COUNTIF('Test Cases'!$M:$M,$A23)
A25: Priority | B25: Test cases
A26: P1 | B26: =COUNTIF('Test Cases'!$E:$E,$A26)
A27: P2 | B27: =COUNTIF('Test Cases'!$E:$E,$A27)
A28: P3 | B28: =COUNTIF('Test Cases'!$E:$E,$A28)
A30: Priority key
A31: P1 – critical path / data integrity; include in every smoke cycle
A32: P2 – important business rule or common negative path
A33: P3 – low-risk or cosmetic behaviour
A35: Record results on the Test Cases sheet (yellow columns): Actual Result and Status (Not Run / Pass / Fail / Blocked).
A37: Release execution plan
A38: Release | B38: Cadence | C38: Scope | D38: Test cases | E38: Entry criteria | F38: Exit criteria
A39: Minor release | B39: Bi-weekly | C39: All P1 + P2 cases; add P3 cases only for modules changed in the release | D39: =COUNTIF('Test Cases'!$E:$E,"P1")+COUNTIF('Test Cases'!$E:$E,"P2") | E39: Build deployed to QA; release notes available; P1 smoke passes | F39: All P1 pass; no open Critical/High defects; fixed defects retested
A40: Major release | B40: Quarterly | C40: Full pack (P1 + P2 + P3); re-verify every item on the Findings sheet | D40: =COUNTA('Test Cases'!$A:$A)-1 | E40: Feature-complete build on QA; DB migrations applied; P1 smoke passes | F40: All cases executed; pass rate >= 98%; no open Critical/High defects; Findings re-checked

Sheet Test Cases
A1: TC ID | B1: Module | C1: Title / Scenario | D1: Type | E1: Priority | F1: Preconditions | G1: Method | H1: Endpoint | I1: Test Data | J1: Steps | K1: Expected Result | L1: Actual Result | M1: Status | N1: Remarks
A2: API-PART-001 | B2: Part CRUD | C2: Create part with only the required field | D2: Positive | E2: P1 | F2: Valid admin API token | G2: POST | H2: /api/part/ | I2: {"name": "<unique>"} | J2: 1. POST the payload 2. Inspect response body | K2: 201 Created; body matches Part schema; name echoed; active=true by default; category=null; IPN blank; in_stock 0/null | M2: Not Run
A3: API-PART-002 | B3: Part CRUD | C3: Create part with all writable attributes | D3: Positive | E3: P1 | F3: Valid admin API token; category C and stock location L exist | G3: POST | H3: /api/part/ | I3: name, IPN, revision=A, keywords, units=m, link, minimum_stock=5, default_expiry=30, category=C, default_location=L, assembly/component/trackable/salable flags, notes | J3: 1. POST payload 2. Compare every field in response | K3: 201; every supplied value persisted verbatim; category_name = C.name; full_name contains IPN and name | M3: Not Run
A4: API-PART-003 | B4: Part CRUD | C4: Retrieve part by ID | D4: Positive | E4: P1 | F4: Valid admin API token; part exists | G4: GET | H4: /api/part/{id}/ | I4: id of existing part | J4: 1. GET /api/part/{id}/ | K4: 200; schema-valid; pk and name match the created part | M4: Not Run
A5: API-PART-004 | B5: Part CRUD | C5: Retrieve part with category_detail and path_detail | D5: Positive | E5: P3 | F5: Valid admin API token; part in category C | G5: GET | H5: /api/part/{id}/ | I5: ?category_detail=true&path_detail=true | J5: 1. GET with detail flags | K5: 200; category_detail.pk = C; last category_path entry = C | M5: Not Run
A6: API-PART-005 | B6: Part CRUD | C6: PATCH updates only supplied fields | D6: Positive | E6: P1 | F6: Valid admin API token; part with description + keywords | G6: PATCH | H6: /api/part/{id}/ | I6: {"description": "after"} | J6: 1. PATCH description only 2. GET the part | K6: 200; description updated and persisted; keywords and name unchanged | M6: Not Run
A7: API-PART-006 | B7: Part CRUD | C7: PUT replaces part | D7: Positive | E7: P2 | F7: Valid admin API token; part exists | G7: PUT | H7: /api/part/{id}/ | I7: {"name": "<new>", "description": "via PUT"} | J7: 1. PUT full representation | K7: 200; name and description replaced | M7: Not Run
A8: API-PART-007 | B8: Part CRUD | C8: PUT without required name | D8: Negative | E8: P2 | F8: Valid admin API token; part exists | G8: PUT | H8: /api/part/{id}/ | I8: {"description": "no name"} | J8: 1. PUT payload lacking name | K8: 400; error keyed on 'name'; record unchanged | M8: Not Run
A9: API-PART-008 | B9: Part CRUD | C9: Toggle each boolean attribute (assembly, component, trackable, purchaseable, salable, virtual, is_template, testable, consumable) | D9: Positive | E9: P2 | F9: Valid admin API token | G9: PATCH | H9: /api/part/{id}/ | I9: {flag: true} then {flag: false} | J9: 1. Create with flag=false 2. PATCH true 3. PATCH false | K9: 200 each time; flag reflects last value | M9: Not Run
A10: API-PART-009 | B10: Part CRUD | C10: Delete an inactive part | D10: Positive | E10: P1 | F10: Valid admin API token; part exists | G10: DELETE | H10: /api/part/{id}/ | I10: PATCH active=false first | J10: 1. PATCH active=false 2. DELETE 3. GET | K10: DELETE 204; subsequent GET 404 | M10: Not Run
A11: API-PART-010 | B11: Part CRUD | C11: Delete an active part is blocked | D11: Negative | E11: P1 | F11: Valid admin API token; active part | G11: DELETE | H11: /api/part/{id}/ | I11: - | J11: 1. DELETE active part 2. GET | K11: 400 with message about active part; record still retrievable (200) | M11: Not Run
A12: API-PART-011 | B12: Part CRUD | C12: Delete a locked part is blocked | D12: Negative | E12: P2 | F12: Valid admin API token; inactive + locked part | G12: DELETE | H12: /api/part/{id}/ | I12: PATCH active=false, locked=true | J12: 1. Lock part 2. DELETE | K12: 400 mentioning 'locked'; record still exists | M12: Not Run
A13: API-PART-012 | B13: Part CRUD | C13: List reflects create and delete | D13: Positive | E13: P2 | F13: Valid admin API token | G13: GET | H13: /api/part/ | I13: ?search=<name> | J13: 1. Create 2. Search -> present 3. Deactivate + delete 4. Search | K13: Part listed after create; absent after delete | M13: Not Run
... A26: API-CAT-013 | B26: Category CRUD | C26: PUT category without name | D26: Negative | E26: P2 | F26: Valid admin API token | G26: PUT | H26: /api/part/category/{id}/ | I26: {"description": "x"} | J26: 1. PUT | K26: 400 on 'name' | M26: Not Run
A27: API-CAT-014 | B27: Category CRUD | C27: DELETE without cascade flags | D27: Negative | E27: P1 | F27: Valid admin API token | G27: DELETE | H27: /api/part/category/{id}/ | I27: (no body) | J27: 1. DELETE with empty body 2. GET | K27: 400 listing delete_parts and delete_child_categories as required; category not deleted. NOTE: not documented in OpenAPI | M27: Not Run | N27: Undocumented mandatory body on DELETE
A28: API-CAT-015 | B28: Category CRUD | C28: Delete with delete_parts=true removes contained parts | D28: Positive | E28: P2 | F28: Valid admin API token; inactive part in category | G28: DELETE | H28: /api/part/category/{id}/ | I28: {"delete_parts": true} | J28: 1. DELETE 2. GET part | K28: 204; part 404 | M28: Not Run
A29: API-LIST-001 | B29: Filtering | C29: category filter without cascade | D29: Positive | E29: P1 | F29: Seeded catalogue (12 parts: 10 in Root, 2 in Child) | G29: GET | H29: /api/part/ | I29: ?category=Root&cascade=false | J29: 1. GET | K29: Only the 10 parts directly in Root | M29: Not Run
A30: API-LIST-002 | B30: Filtering | C30: category filter with cascade | D30: Positive | E30: P1 | F30: Seeded catalogue | G30: GET | H30: /api/part/ | I30: ?category=Root&cascade=true | J30: 1. GET | K30: All 12 parts | M30: Not Run
A31: API-LIST-003 | B31: Filtering | C31: Filter by leaf category | D31: Positive | E31: P2 | F31: Seeded catalogue | G31: GET | H31: /api/part/ | I31: ?category=Child | J31: 1. GET | K31: P03, P04 only | M31: Not Run
A32: API-LIST-004 | B32: Filtering | C32: exclude_id with comma-separated IDs | D32: Positive | E32: P3 | F32: Seeded catalogue | G32: GET | H32: /api/part/ | I32: ?exclude_id=P01,P02 | J32: 1. GET | K32: 10 parts; P01/P02 absent | M32: Not Run
A33: API-LIST-005 | B33: Filtering | C33: Malformed boolean filter value | D33: Boundary | E33: P3 | F33: Seeded catalogue | G33: GET | H33: /api/part/ | I33: ?active=notbool | ?active=2 | J33: 1. GET | K33: No 5xx (200 or 400) | M33: Not Run
A34: API-LIST-010 | B34: Filtering | C34: Filter: active=false | D34: Positive | E34: P2 | F34: Seeded catalogue (12 parts P01–P12 with known flags) | G34: GET | H34: /api/part/ | I34: ?category=Root&cascade=true&active=false | J34: 1. GET with filter scoped to seeded tree | K34: 200; result set is exactly P03 | M34: Not Run
A35: API-LIST-011 | B35: Filtering | C35: Filter: assembly=true | D35: Positive | E35: P2 | F35: Seeded catalogue (12 parts P01–P12 with known flags) | G35: GET | H35: /api/part/ | I35: ?category=Root&cascade=true&assembly=true | J35: 1. GET with filter scoped to seeded tree | K35: 200; result set is exactly P01 | M35: Not Run
A36: API-LIST-012 | B36: Filtering | C36: Filter: component=true | D36: Positive | E36: P2 | F36: Seeded catalogue (12 parts P01–P12 with known flags) | G36: GET | H36: /api/part/ | I36: ?category=Root&cascade=true&component=true | J36: 1. GET with filter scoped to seeded tree | K36: 200; result set is exactly P02, P03, P06, P07, P08, P09, P10, P11, P12 | M36: Not Run
A37: API-LIST-013 | B37: Filtering | C37: Filter: purchaseable=true | D37: Positive | E37: P2 | F37: Seeded catalogue (12 parts P01–P12 with known flags) | G37: GET | H37: /api/part/ | I37: ?category=Root&cascade=true&purchaseable=true | J37: 1. GET with filter scoped to seeded tree | K37: 200; result set is exactly P02, P06, P07, P08, P09, P10, P11, P12 | M37: Not Run
A38: API-LIST-014 | B38: Filtering | C38: Filter: salable=true | D38: Positive | E38: P2 | F38: Seeded catalogue (12 parts P01–P12 with known flags) | G38: GET | H38: /api/part/ | I38: ?category=Root&cascade=true&salable=true | J38: 1. GET with filter scoped to seeded tree | K38: 200; result set is exactly P03, P05 | M38: Not Run
A39: API-LIST-015 | B39: Filtering | C39: Filter: trackable=true | D39: Positive | E39: P2 | F39: Seeded catalogue (12 parts P01–P12 with known flags) | G39: GET | H39: /api/part/ | I39: ?category=Root&cascade=true&trackable=true | J39: 1. GET with filter scoped to seeded tree | K39: 200; result set is exactly P04 | M39: Not Run
... A83: API-REL-024 | B83: Relational Integrity | C83: initial_stock creates a stock item at location | D83: Positive | E83: P1 | F83: Valid admin API token; location L | G83: POST | H83: /api/part/ | I83: {"initial_stock": {"quantity": 25, "location": L}} | J83: 1. POST 2. GET /api/stock/?part= 3. GET part | K83: 1 stock item, qty 25 at L; part.in_stock 25 | M83: Not Run
A84: API-REL-026 | B84: Relational Integrity | C84: Part inherits default location from top-level ancestor | D84: Positive | E84: P2 | F84: Valid admin API token; top-level category with default_location L; child | G84: GET | H84: /api/part/{id}/ | I84: - | J84: 1. Part in child 2. GET part | K84: category_default_location = L (DEFECT: returns null) | M84: Not Run | N84: DEF-02: top-level ancestor default ignored
A85: API-REL-030 | B85: Relational Integrity | C85: initial_supplier creates linked SupplierPart + ManufacturerPart | D85: Positive | E85: P1 | F85: Valid admin API token; supplier S, manufacturer M | G85: POST | H85: /api/part/ | I85: {"initial_supplier": {"supplier": S, "sku", "manufacturer": M, "mpn"}} | J85: 1. POST 2. GET /api/company/part/?part= 3. GET /api/company/part/manufacturer/?part= | K85: 1 supplier part (SKU, supplier S); 1 manufacturer part (MPN, M); supplier part links to manufacturer part | M85: Not Run
A86: API-REL-031 | B86: Relational Integrity | C86: initial_supplier with non-supplier company | D86: Negative | E86: P2 | F86: Valid admin API token | G86: POST | H86: /api/part/ | I86: supplier=<customer company> | J86: 1. POST | K86: 400 'not a valid supplier' | M86: Not Run
A87: API-REL-040 | B87: Relational Integrity | C87: Duplicate name + IPN + revision | D87: Negative | E87: P1 | F87: Valid admin API token | G87: POST | H87: /api/part/ | I87: same name/IPN/revision | J87: 1. POST duplicate | K87: 400 (uniqueness conflict) | M87: Not Run
A88: API-SEC-001 | B88: Security | C88: Requests without credentials are rejected on list, create and detail endpoints | D88: Negative | E88: P1 | F88: No Authorization header; a part exists | G88: GET / POST / PATCH / DELETE | H88: /api/part/ , /api/part/{id}/ , /api/part/category/ | I88: - | J88: 1. Call each endpoint and method anonymously 2. As admin, verify the record is unchanged and nothing was created | K88: 401 Unauthorized for every call; no side-effects | M88: Not Run
A89: API-SEC-003 | B89: Security | C89: Invalid / malformed Authorization header | D89: Negative | E89: P1 | F89: - | G89: GET | H89: /api/part/ | I89: 'Token bad', 'Token ', 'Bearer x', 'garbage' | J89: 1. GET | K89: 401 | M89: Not Run
A90: API-SEC-010 | B90: Security | C90: View-only user: read allowed, writes forbidden | D90: Negative | E90: P1 | F90: User with view-only Part/Category role | G90: GET/POST/PATCH/DELETE | H90: /api/part/ , /api/part/category/ | I90: - | J90: 1. GET list & detail 2. POST part & category 3. PATCH 4. DELETE | K90: GET 200; POST/PATCH/DELETE 403 | M90: Not Run | N90: Requires a user with view-only Part/Category role
A91: API-EDGE-001 | B91: Edge Cases | C91: Non-existent part/category IDs (GET, PATCH, PUT, DELETE) | D91: Negative | E91: P1 | F91: Valid admin API token | G91: ALL | H91: /api/part/{id}/ , /api/part/category/{id}/ | I91: id=999999999 | J91: 1. Call each method | K91: 404 | M91: Not Run
A92: API-EDGE-010 | B92: Edge Cases | C92: Malformed JSON body | D92: Negative | E92: P2 | F92: Valid admin API token | G92: POST | H92: /api/part/ | I92: {"name": "broken", | J92: 1. POST | K92: 400 parse error | M92: Not Run
A93: API-EDGE-011 | B93: Edge Cases | C93: Unsupported Content-Type | D93: Negative | E93: P3 | F93: Valid admin API token | G93: POST | H93: /api/part/ | I93: text/plain | J93: 1. POST | K93: 415 | M93: Not Run
A94: API-EDGE-012 | B94: Edge Cases | C94: Non-object JSON body (array, string, number) | D94: Negative | E94: P2 | F94: Valid admin API token | G94: POST | H94: /api/part/ | I94: [], [{…}], "str", 42 | J94: 1. POST | K94: 400 (DEFECT: returns 500) | M94: Not Run | N94: DEF-01: server returns 500
A95: API-EDGE-030 | B95: Edge Cases | C95: Concurrent updates: last write wins | D95: Boundary | E95: P2 | F95: Valid admin API token x2 sessions | G95: PATCH | H95: /api/part/{id}/ | I95: writer-1 then writer-2 | J95: 1. PATCH from session A 2. PATCH from session B 3. GET | K95: 200 both; final value writer-2 (no optimistic locking) | M95: Not Run | N95: No ETag / If-Match support; documents current behaviour
...

Sheet Scope & Endpoints
A1: Schema analysis – endpoint inventory (Parts & Part Categories)
A3: Endpoint | B3: Methods | C3: In scope | D3: Purpose | E3: Key behaviours derived from schema / server
A4: /api/part/ | B4: GET, POST, PATCH, PUT | C4: Yes | D4: List / create parts; bulk PATCH/PUT | E4: Paginated via limit/offset (array when limit omitted); ~50 filters; search over IPN, category name, description, keywords, MPN, name, revision, SKU, tags
A5: /api/part/{id}/ | B5: GET, PATCH, PUT, DELETE | C5: Yes | D5: Retrieve / update / delete a part | E5: DELETE blocked for active or locked parts, or parts used in an assembly
A6: /api/part/category/ | B6: GET, POST, PATCH, PUT | C6: Yes | D6: List / create categories | E6: Filters: parent, structural, search; paginated
A7: /api/part/category/{id}/ | B7: GET, PATCH, PUT, DELETE | C7: Yes | D7: Retrieve / update / delete a category | E7: DELETE requires body {delete_parts, delete_child_categories} (not in spec); default re-parents children and parts
A8: /api/part/category/tree/ | B8: GET | C8: Yes | D8: Flat tree listing | E8: Used to verify hierarchy
A9: /api/stock/location/ | B9: GET, POST | C9: Supporting | D9: Default-location fixtures | E9: DELETE requires {delete_stock_items, delete_sub_locations}
A10: /api/company/, /api/company/part/, /api/company/part/manufacturer/ | B10: GET, POST | C10: Supporting | D10: Supplier linkage verification | E10: initial_supplier on part create spawns SupplierPart (+ ManufacturerPart)
A11: /api/stock/ | B11: GET | C11: Supporting | D11: initial_stock verification | E11: -
A12: /api/user/token/ | B12: GET | C12: Supporting | D12: Token exchange (basic auth) | E12: Auth header: 'Token <key>'
A13: /api/part/category/parameters/, internal-price, sale-price, related, stocktake, test-template, thumbs, {id}/bom-*, pricing, requirements, serial-numbers | B13: various | C13: No | D13: Out of scope for this phase | E13: Candidate for next phase
A16: Authentication schemes in spec: tokenAuth ('Token' prefix), basicAuth, cookieAuth, oauth2.

Sheet Field Constraints
A1: Field constraint matrix (from OpenAPI v530, verified against live OPTIONS)
A3: Resource | B3: Field | C3: Type | D3: Required | E3: Max length | F3: Nullable | G3: Read-only | H3: Write-only | I3: Other rules | J3: Covered by
A4: Part | B4: name | C4: string | D4: Yes | E4: 100 | F4: No | G4: No | H4: No | I4: Unique with IPN + revision; HTML rejected | J4: API-VAL-001/004/005, API-REL-040
A5: Part | B5: description | C5: string | D5: No | E5: 250 | F5: No | G5: No | H5: No | I5: HTML rejected | J5: API-VAL-007/053
A6: Part | B6: IPN | C6: string | D6: No | E6: 100 | F6: No | G6: No | H6: No | I6: Duplicate IPN governed by PART_ALLOW_DUPLICATE_IPN | J6: API-VAL-009
A7: Part | B7: revision | C7: string | D7: No | E7: 100 | F7: Yes | G7: No | H7: No | J7: API-REL-040
A8: Part | B8: keywords | C8: string | D8: No | E8: 250 | F8: Yes | G8: No | H8: No | J8: API-VAL-026
A9: Part | B9: units | C9: string | D9: No | E9: 20 | F9: Yes | G9: No | H9: No | I9: Must be a valid physical unit (pint) | J9: API-VAL-016/026
A10: Part | B10: link | C10: uri | D10: No | E10: 2000 | F10: Yes | G10: No | H10: No | I10: Must be a URL | J10: API-VAL-018/026
A11: Part | B11: notes | C11: string (markdown) | D11: No | E11: 50000 | F11: Yes | G11: No | H11: No | J11: -
A12: Part | B12: category | C12: integer FK | D12: No | E12: - | F12: Yes | G12: No | H12: No | I12: Not structural; must exist | J12: API-VAL-024/026, API-REL-001/002/005
A13: Part | B13: default_location | C13: integer FK | D13: No | E13: - | F13: Yes | G13: No | H13: No | I13: SET_NULL on location delete | J13: API-REL-020/021
A14: Part | B14: default_expiry | C14: int64 | D14: No | E14: - | F14: No | G14: No | H14: No | I14: minimum 0 | J14: API-VAL-020
A15: Part | B15: minimum_stock | C15: double | D15: No | E15: - | F15: No | G15: No | H15: No | I15: ≥ 0 | J15: -
A16: Part | B16: active / assembly / component / … flags | C16: boolean | D16: No | E16: - | F16: No | G16: No | H16: No | J16: API-PART-008
A17: Part | B17: variant_of / revision_of | C17: integer FK | D17: No | E17: - | F17: Yes | G17: No | H17: No | J17: -
A18: Part | B18: pk, full_name, barcode_hash, creation_date, in_stock, total_in_stock, stock_item_count, category_name, … | C18: various | D18: - | E18: - | F18: - | G18: Yes | H18: No | I18: Server-derived | J18: API-RO-001
A19: Part | B19: initial_stock | C19: object {quantity, location} | D19: No | E19: - | F19: - | G19: No | H19: Yes | I19: quantity required inside object | J19: API-REL-024
A20: Part | B20: initial_supplier | C20: object {supplier, sku, manufacturer, mpn} | D20: No | E20: - | F20: - | G20: No | H20: Yes | I20: supplier must be is_supplier; SKU/MPN unique | J20: API-REL-030/031
A21: Part | B21: copy_category_parameters, duplicate, existing_image | C21: various | D21: No | E21: - | F21: - | G21: No | H21: Yes | J21: -
A22: Category | B22: name | C22: string | D22: Yes | E22: 100 | F22: No | G22: No | H22: No | I22: Unique per parent | J22: API-CVAL-001/004, API-REL-009
A23: Category | B23: description | C23: string | D23: No | E23: 250 | F23: No | G23: No | H23: No | J23: -
A24: Category | B24: parent | C24: integer FK | D24: No | E24: - | F24: Yes | G24: No | H24: No | I24: No self-reference or cycles | J24: API-CVAL-007, API-REL-008
A25: Category | B25: structural | C25: boolean | D25: No | E25: - | F25: No | G25: No | H25: No | I25: Cannot be set while parts are assigned | J25: API-REL-005
A26: Category | B26: default_location | C26: integer FK | D26: No | E26: - | F26: Yes | G26: No | H26: No | I26: Inherited by sub-categories | J26: API-REL-021/026
A27: Category | B27: pk, level, pathstring, part_count, subcategories | C27: various | D27: - | E27: - | F27: - | G27: Yes | H27: No | J27: API-RO-010

Sheet Findings
A1: Defects and specification deviations observed on InvenTree 1.5.5 (API v530)
A3: ID | B3: Type | C3: Severity | D3: Title | E3: Steps to reproduce | F3: Expected | G3: Actual | H3: Evidence / root cause | I3: Linked TC
A4: DEF-01 | B4: Defect | C4: Medium | D4: Non-object JSON body on POST /api/part/ causes HTTP 500 | E4: POST /api/part/ with body [] or "str" or 42 (Content-Type: application/json) | F4: 400 Bad Request with validation message | G4: 500 Internal Server Error: AttributeError '<type>' object has no attribute 'items' | H4: Unhandled type in request-data cleaning before serializer validation | I4: API-EDGE-012
A5: DEF-02 | B5: Defect | C5: Low | D5: Part.category_default_location ignores default set on a top-level ancestor | E5: 1. Category TOP (no parent) with default_location L 2. Child category under TOP 3. Part in child 4. GET part | F5: category_default_location = L (as Part.get_default_location() returns) | G5: null | H5: part/filters.py annotate_default_location(): ancestor subquery filters parent__isnull=False, excluding the root node | I5: API-REL-026
A6: DEV-01 | B6: Spec deviation | C6: Low | D6: category_name marked required in OpenAPI but omitted for uncategorised parts | E6: Create part with category=null; GET it | F6: category_name present (null or empty) | G6: Key absent | H6: Breaks strict schema-generated clients | I6: API-CON-003
A7: DEV-02 | B7: Inconsistency | C7: Low | D7: POST 201 response returns null for computed stock fields | E7: POST /api/part/ then GET the same id | F7: Same values in both | G7: POST: in_stock/total_in_stock/stock_item_count = null; GET: 0 | H7: Annotations not applied to the create response queryset | I7: API-CON-004
A8: DEV-03 | B8: Undocumented rule | C8: Info | D8: DELETE category / stock location requires cascade flags in the body | E8: DELETE /api/part/category/{id}/ with no body | F8: 204 using documented defaults | G8: 400: delete_parts and delete_child_categories are required. Also returns 400, not 404, for a non-existent id without a body | H8: CategoryDeleteSerializer is validated before the object lookup | I8: API-CAT-014

Sheet Traceability
A1: Requirement → test case traceability (Phase 2 brief)
A3: Req | B3: Requirement (from brief) | C3: TC ID prefixes | D3: Test cases
A4: R1 | B4: CRUD operations on Parts | C4: API-PART-* | D4: =COUNTIF('Test Cases'!$A:$A,"API-PART-*")
A5: R2 | B5: CRUD operations on Part Categories | C5: API-CAT-* | D5: =COUNTIF('Test Cases'!$A:$A,"API-CAT-*")
A6: R3 | B6: Filtering on the Parts list endpoint | C6: API-LIST-*, API-SORT-* | D6: =COUNTIF('Test Cases'!$A:$A,"API-LIST-*")+COUNTIF('Test Cases'!$A:$A,"API-SORT-*")
A7: R4 | B7: Pagination on the Parts list endpoint | C7: API-PAGE-* | D7: =COUNTIF('Test Cases'!$A:$A,"API-PAGE-*")
A8: R5 | B8: Search on the Parts list endpoint | C8: API-SRCH-* | D8: =COUNTIF('Test Cases'!$A:$A,"API-SRCH-*")
A9: R6 | B9: Field-level validation: required, max length, nullable, read-only | C9: API-VAL-*, API-CVAL-*, API-RO-*, API-CON-* | D9: =COUNTIF('Test Cases'!$A:$A,"API-VAL-*")+COUNTIF('Test Cases'!$A:$A,"API-CVAL-*")+COUNTIF('Test Cases'!$A:$A,"API-RO-*")+COUNTIF('Test Cases'!$A:$A,"API-CON-*")
A10: R7 | B10: Relational integrity: category assignment, default locations, supplier linkage | C10: API-REL-* | D10: =COUNTIF('Test Cases'!$A:$A,"API-REL-*")
A11: R8 | B11: Edge cases: invalid payloads, unauthorised access, conflict scenarios | C11: API-SEC-*, API-EDGE-* | D11: =COUNTIF('Test Cases'!$A:$A,"API-SEC-*")+COUNTIF('Test Cases'!$A:$A,"API-EDGE-*")
A13: Conflict scenarios for R8 are covered by API-EDGE-030/031 plus API-REL-009 and API-REL-040 (counted under R7).

Sheet Automation Traceability 
A1: TC ID | B1: Automated | C1: Test Class.Method | D1: Coverage Note
A2: API-PART-001 | B2: Yes | C2: InvenTreePartE2ETest.apiPart001CreateMinimalPart | D2: Full match.
A3: API-PART-002 | B3: Partial | C3: InvenTreePartE2ETest.apiPart002CreatePartWithWritableAttributes | D3: Covers revision/keywords/units/description/notes/component/assembly/consumable/purchaseable/salable/trackable/testable + category/default_location. link, minimum_stock and default_expiry are not included in this payload.
A4: API-PART-003 | B4: Yes | C4: InvenTreePartE2ETest.apiPart003RetrievePartById | D4: Full match.
A5: API-PART-004 | B5: Yes | C5: InvenTreePartE2ETest.apiPart004RetrievePartWithDetailFlags | D5: Full match (category_detail + path_detail).
A6: API-PART-005 | B6: Yes | C6: InvenTreePartE2ETest.apiPart005PatchOnlySuppliedFields | D6: Full match.
A7: API-PART-006 | B7: Yes | C7: InvenTreePartE2ETest.apiPart006PutReplacement | D7: Full match.
A8: API-PART-007 | B8: Yes | C8: InvenTreePartE2ETest.apiPart007RejectPutWithoutName | D8: Full match.
A9: API-PART-008 | B9: No
A10: API-PART-009 | B10: Yes | C10: InvenTreePartE2ETest.apiPart009DeleteInactivePart | D10: Full match.
A11: API-PART-010 | B11: Yes | C11: InvenTreePartE2ETest.apiPart010BlockDeleteActivePart | D11: Full match.
A12: API-PART-011 | B12: Yes | C12: InvenTreePartE2ETest.apiPart011BlockDeleteLockedPart | D12: Full match.
A13: API-PART-012 | B13: No
A14: API-CAT-001 | B14: Yes | C14: InvenTreePartCategoryE2ETest.catCreateMinimal | D14: Full match.
A15: API-CAT-002 | B15: Partial | C15: InvenTreePartCategoryE2ETest.catCreateChildAndVerifyPath | D15: Only 2 levels tested (parent/child), not 3 (parent/child/grandchild); parent.subcategories count not verified.
A16: API-CAT-003 | B16: Yes | C16: InvenTreePartCategoryE2ETest.catRetrieveById | D16: Full match.
A17: API-CAT-004 | B17: No
A18: API-CAT-005 | B18: No
A19: API-CAT-006 | B19: Yes | C19: InvenTreePartCategoryE2ETest.catPutReplacement | D19: Full match.
A20: API-CAT-007 | B20: No
A21: API-CAT-008 | B21: No
A22: API-CAT-009 | B22: Partial | C22: InvenTreePartCategoryE2ETest.catDeleteOrphansAssignedPart | D22: Verifies the part's re-parenting to the grandparent on default delete; does not test a 3rd-level sub-category also re-parenting (leaf.parent).
A23: API-CAT-010 | B23: No
A24: API-CAT-011 | B24: No
A25: API-CAT-012 | B25: No
A26: API-CAT-013 | B26: Yes | C26: InvenTreePartCategoryE2ETest.catRejectPutWithoutName | D26: Full match.
A27: API-CAT-014 | B27: Yes | C27: InvenTreePartCategoryE2ETest.catRejectDeleteWithoutCascadeFlags | D27: Full match.
A28: API-CAT-015 | B28: No
A29: API-LIST-001 | B29: Partial | C29: InvenTreePartListQueryTest.filteringByCategoryReturnsOnlyMatchingParts | D29: Verifies category-filter inclusion/exclusion with 2 fixture parts; doesn't exercise the explicit cascade=false param or the 12-part seeded-count matrix this TC specifies.
A30: API-LIST-002 | B30: No
A31: API-LIST-003 | B31: No
A32: API-LIST-004 | B32: No
A33: API-LIST-005 | B33: No
A34: API-LIST-010 | B34: No
A35: API-LIST-011 | B35: No
A36: API-LIST-012 | B36: No
A37: API-LIST-013 | B37: No
A38: API-LIST-014 | B38: No
A39: API-LIST-015 | B39: No
A40: API-LIST-016 | B40: No
...
